---
description: '詳細情報: C6312'
title: C6312
ms.date: 11/04/2016
ms.topic: reference
f1_keywords:
- C6312
helpviewer_keywords:
- C6312
ms.assetid: 1fc8b9a1-e6ba-4799-84c3-31f289576cca
ms.openlocfilehash: e53a4701df3f65c2365bee0fe8492b044643801f
ms.sourcegitcommit: d6af41e42699628c3e2e6063ec7b03931a49a098
ms.translationtype: MT
ms.contentlocale: ja-JP
ms.lasthandoff: 12/11/2020
ms.locfileid: "97321070"
---
# <a name="c6312"></a>C6312

> 警告 C6312: 無限ループが発生している可能性があります: try-except の例外フィルター式で定数 EXCEPTION_CONTINUE_EXECUTION が使用されています。

この警告 `EXCEPTION_CONTINUE_EXECUTION` は、構造化例外ハンドラーのフィルター式で定数 (または-1 に評価される別の定数) を使用していることを示します。 定数値を使用すると、 `EXCEPTION_CONTINUE_EXECUTION` 無限ループに陥る可能性があります。 たとえば、ハードウェアによって例外が発生した場合、例外の原因となった命令が再起動されます。 例外の原因となったアドレスが依然として間違っている場合は、別の例外が発生し、同じ方法で処理されます。 これにより、無限ループが発生します。

を明示的に呼び出すと、 `RaiseException` 無限ループは直接発生しませんが、保護されたブロック内のコードの実行は続行されます。 これは予期しない場合があり `RaiseException` ます。また、が無効なポインターの逆参照を避けるために使用された場合、無限ループが発生する可能性があります。

通常、は、 `EXCEPTION_CONTINUE_EXECUTION` フィルター式で呼び出された関数によってのみ返される必要があります。この場合、例外の原因となったポインターまたは基になるメモリを修正する機会があります。

## <a name="example"></a>例

この警告が発生するコード例を次に示します。

```cpp
#include <excpt.h>
#include <stdio.h>
#include <windows.h>

void f (char *ptr)
{
  __try
  {
    // exception occurs if the caller passes null ptr
    // code...
    *ptr = '\0';
  }
  __except (EXCEPTION_CONTINUE_EXECUTION)
    // When EXCEPTION_CONTINUE_EXECUTION is used, the handler
    //  block of the structured exception handler is not executed.
  {
    puts("This block is never executed");
  }
}
```

この警告を解決するには、次のコードを使用します。

```cpp
#include <excpt.h>
#include <stdio.h>
#include <windows.h>

void f (char *ptr)
{
  __try
  {
    // exception occurs if the caller passes null ptr
    // code...
    *ptr = '\0';
  }
  __except (GetExceptionCode()== EXCEPTION_ACCESS_VIOLATION ?
               EXCEPTION_EXECUTE_HANDLER : EXCEPTION_CONTINUE_SEARCH)
  {
    puts("Error Occurred");
  }
}
```
