---
title: C6312
ms.date: 11/04/2016
ms.topic: reference
f1_keywords:
- C6312
helpviewer_keywords:
- C6312
ms.assetid: 1fc8b9a1-e6ba-4799-84c3-31f289576cca
ms.openlocfilehash: cf9e04a76e174eca084d4b6f4c83ab3f504560f9
ms.sourcegitcommit: 7bea0420d0e476287641edeb33a9d5689a98cb98
ms.translationtype: MT
ms.contentlocale: ja-JP
ms.lasthandoff: 02/17/2020
ms.locfileid: "79468061"
---
# <a name="c6312"></a>C6312

> 警告 C6312: 無限ループが発生している可能性があります: try-except の例外フィルター式で定数 EXCEPTION_CONTINUE_EXECUTION が使用されています。

この警告は、構造化例外ハンドラーのフィルター式で定数 `EXCEPTION_CONTINUE_EXECUTION` (または-1 に評価される別の定数) の使用を示しています。 `EXCEPTION_CONTINUE_EXECUTION` 定数値を使用すると、無限ループにつながる可能性があります。 たとえば、ハードウェアによって例外が発生した場合、例外の原因となった命令が再起動されます。 例外の原因となったアドレスが依然として間違っている場合は、別の例外が発生し、同じ方法で処理されます。 これにより、無限ループが発生します。

`RaiseException` を明示的に呼び出すと、無限ループは直接発生しませんが、保護されたブロック内のコードの実行は続行されます。 これは予期しない可能性があります。無効なポインターの逆参照を避けるために `RaiseException` を使用した場合、無限ループが発生する可能性があります。

通常、`EXCEPTION_CONTINUE_EXECUTION` は、フィルター式で呼び出された関数によってのみ返される必要があります。この場合、例外の原因となったポインターまたは基になるメモリを修正する機会があります。

## <a name="example"></a>例

この警告が発生するコード例を次に示します。

```cpp
#include <excpt.h>
#include <stdio.h>
#include <windows.h>

void f (char *ptr)
{
  __try
  {
    // exception occurs if the caller passes null ptr
    // code...
    *ptr = '\0';
  }
  __except (EXCEPTION_CONTINUE_EXECUTION)
    // When EXCEPTION_CONTINUE_EXECUTION is used, the handler
    //  block of the structured exception handler is not executed.
  {
    puts("This block is never executed");
  }
}
```

この警告を解決するには、次のコードを使用します。

```cpp
#include <excpt.h>
#include <stdio.h>
#include <windows.h>

void f (char *ptr)
{
  __try
  {
    // exception occurs if the caller passes null ptr
    // code...
    *ptr = '\0';
  }
  __except (GetExceptionCode()== EXCEPTION_ACCESS_VIOLATION ?
               EXCEPTION_EXECUTE_HANDLER : EXCEPTION_CONTINUE_SEARCH)
  {
    puts("Error Occurred");
  }
}
```
