---
title: C6322
ms.date: 11/04/2016
ms.topic: reference
f1_keywords:
- C6322
helpviewer_keywords:
- C6322
ms.assetid: fb23d2b1-b2a0-465c-8bf5-ec039c6c7757
ms.openlocfilehash: 47e65bfa5b350f298bf26e739a35b0f8ff4c517c
ms.sourcegitcommit: 7bea0420d0e476287641edeb33a9d5689a98cb98
ms.translationtype: MT
ms.contentlocale: ja-JP
ms.lasthandoff: 02/17/2020
ms.locfileid: "79467953"
---
# <a name="c6322"></a>C6322

> 警告 C6322: 空の _except ブロックです

このメッセージは、_except ブロックにコードがないことを示しています。 その結果、例外が処理されなくなる可能性があります。

## <a name="example"></a>例

この警告が発生するコード例を次に示します。

```cpp
#include <stdio.h>
#include <excpt.h>
#include <windows.h>

void fd(char *pch)
{
   __try
   {
     // exception rasied if pch is null
     *pch= 0 ;
   }
   __except(GetExceptionCode() == EXCEPTION_ACCESS_VIOLATION)
   {
   }
}
```

この警告を解決するには、次のコードを使用します。

```cpp
#include <stdio.h>
#include <excpt.h>
#include <windows.h>

void f(char *pch)
{
   __try
   {
     // exception rasied if pch is null
    *pch= 0 ;
   }
   __except(GetExceptionCode() == EXCEPTION_ACCESS_VIOLATION ?
               EXCEPTION_EXECUTE_HANDLER : EXCEPTION_CONTINUE_SEARCH)
   {
     // code to handle exception
     puts("Exception Occurred");
   }
}
```

## <a name="see-also"></a>参照

[try-except ステートメント](/cpp/cpp/try-except-statement)
